Traceback (most recent call last):
  File "/Users/eelco/opt/anaconda3/envs/jupyterbook/lib/python3.9/site-packages/jupyter_cache/executors/utils.py", line 51, in single_nb_execution
    executenb(
  File "/Users/eelco/opt/anaconda3/envs/jupyterbook/lib/python3.9/site-packages/nbclient/client.py", line 1112, in execute
    return NotebookClient(nb=nb, resources=resources, km=km, **kwargs).execute()
  File "/Users/eelco/opt/anaconda3/envs/jupyterbook/lib/python3.9/site-packages/nbclient/util.py", line 74, in wrapped
    return just_run(coro(*args, **kwargs))
  File "/Users/eelco/opt/anaconda3/envs/jupyterbook/lib/python3.9/site-packages/nbclient/util.py", line 53, in just_run
    return loop.run_until_complete(coro)
  File "/Users/eelco/opt/anaconda3/envs/jupyterbook/lib/python3.9/asyncio/base_events.py", line 642, in run_until_complete
    return future.result()
  File "/Users/eelco/opt/anaconda3/envs/jupyterbook/lib/python3.9/site-packages/nbclient/client.py", line 553, in async_execute
    await self.async_execute_cell(
  File "/Users/eelco/opt/anaconda3/envs/jupyterbook/lib/python3.9/site-packages/nbclient/client.py", line 857, in async_execute_cell
    self._check_raise_for_error(cell, exec_reply)
  File "/Users/eelco/opt/anaconda3/envs/jupyterbook/lib/python3.9/site-packages/nbclient/client.py", line 760, in _check_raise_for_error
    raise CellExecutionError.from_cell_and_msg(cell, exec_reply_content)
nbclient.exceptions.CellExecutionError: An error occurred while executing the following cell:
------------------
object2 = {"naam": "Kees", "leeftijd": "dertig"}
validate(instance=object2, schema=schema)
------------------

[0;31m---------------------------------------------------------------------------[0m
[0;31mValidationError[0m                           Traceback (most recent call last)
[0;32m<ipython-input-4-af16bdf128b7>[0m in [0;36m<module>[0;34m[0m
[1;32m      1[0m [0mobject2[0m [0;34m=[0m [0;34m{[0m[0;34m"naam"[0m[0;34m:[0m [0;34m"Kees"[0m[0;34m,[0m [0;34m"leeftijd"[0m[0;34m:[0m [0;34m"dertig"[0m[0;34m}[0m[0;34m[0m[0;34m[0m[0m
[0;32m----> 2[0;31m [0mvalidate[0m[0;34m([0m[0minstance[0m[0;34m=[0m[0mobject2[0m[0;34m,[0m [0mschema[0m[0;34m=[0m[0mschema[0m[0;34m)[0m[0;34m[0m[0;34m[0m[0m
[0m
[0;32m~/opt/anaconda3/envs/jupyterbook/lib/python3.9/site-packages/jsonschema/validators.py[0m in [0;36mvalidate[0;34m(instance, schema, cls, *args, **kwargs)[0m
[1;32m    932[0m     [0merror[0m [0;34m=[0m [0mexceptions[0m[0;34m.[0m[0mbest_match[0m[0;34m([0m[0mvalidator[0m[0;34m.[0m[0miter_errors[0m[0;34m([0m[0minstance[0m[0;34m)[0m[0;34m)[0m[0;34m[0m[0;34m[0m[0m
[1;32m    933[0m     [0;32mif[0m [0merror[0m [0;32mis[0m [0;32mnot[0m [0;32mNone[0m[0;34m:[0m[0;34m[0m[0;34m[0m[0m
[0;32m--> 934[0;31m         [0;32mraise[0m [0merror[0m[0;34m[0m[0;34m[0m[0m
[0m[1;32m    935[0m [0;34m[0m[0m
[1;32m    936[0m [0;34m[0m[0m

[0;31mValidationError[0m: 'dertig' is not of type 'integer'

Failed validating 'type' in schema['properties']['leeftijd']:
    {'type': 'integer'}

On instance['leeftijd']:
    'dertig'
ValidationError: 'dertig' is not of type 'integer'

Failed validating 'type' in schema['properties']['leeftijd']:
    {'type': 'integer'}

On instance['leeftijd']:
    'dertig'

